Workbook

Sheet README
B2: MAVEN MEDICAL CENTER - Birth Weight Analysis
B4: Project Overview
B5: Role: | C5: Data Analyst at Maven Medical Center, Springfield, MA
B6: Requested by: | C6: Betty Birth, Chief Gynecologist
B7: Subject: | C7: Birth weight probability analysis
B8: Dataset: | C8: 189 birth weight records (Birth_Weights.xlsx)
B9: Tools: | C9: Microsoft Excel (statistical functions, NORM.DIST, NORM.INV)
B11: Key Objectives
B12: 1. Check if the birth weights follow a normal distribution
B13: 2. Calculate the probability of a baby weighing 2.5kg or less
B14: 3. Estimate values at the 1% and 99% cumulative probabilities
B15: 4. Count births under and over those thresholds
B16: 5. Validate distribution using the Empirical Rule
B18: Tab Descriptions
B19: README | C19: This tab — project overview, objectives, methodology
B20: Raw Data | C20: Original 189 birth weight records (untouched)
B21: Analysis | C21: All statistical calculations and analysis
B22: Summary | C22: Key findings and conclusions
B24: Statistical Methods Used
B25: Normal Distribution | C25: NORM.DIST — probability density function
B26: Probability Calculation | C26: NORM.DIST (cumulative) — P(X <= 2.5kg)
B27: Percentile Values | C27: NORM.INV — inverse normal for 1% and 99%
B28: Empirical Rule | C28: 68-95-99.7 rule validation against sample data
B29: Skewness | C29: SKEW function — measure of distribution asymmetry

Sheet Raw Data
A1: Weight (g) | B1: Weight (Kg)
A2: 2523 | B2: 2.523
A3: 2551 | B3: 2.551
A4: 2557 | B4: 2.557
A5: 2594 | B5: 2.594
A6: 2600 | B6: 2.6
A7: 2622 | B7: 2.622
A8: 2637 | B8: 2.637
A9: 2637 | B9: 2.637
A10: 2663 | B10: 2.663
A11: 2665 | B11: 2.665
A12: 2722 | B12: 2.722
A13: 2733 | B13: 2.733
... A190: 2495 | B190: 2.495

Sheet Analysis
A1: 1. DESCRIPTIVE STATISTICS
A3: Metric | B3: Value
A4: Total Records | B4: =COUNT('Raw Data'!A2:A190) -> 189 | D4: Interpretation:
A5: Mean (Kg) | B5: =AVERAGE('Raw Data'!B2:B190) -> 2.9445873 | D5: The mean (2.945 Kg) and median (2.977 Kg) are very close, and skewness is near zero (-0.209), indicating the data approximately follows a normal distribution with a very slight left skew.
A6: Median (Kg) | B6: =MEDIAN('Raw Data'!B2:B190) -> 2.977
A7: Std Deviation (Kg) | B7: =_xlfn.STDEV.S('Raw Data'!B2:B190) -> 0.7292143
A8: Minimum (Kg) | B8: =MIN('Raw Data'!B2:B190) -> 0.709
A9: Maximum (Kg) | B9: =MAX('Raw Data'!B2:B190) -> 4.99
A10: Skewness | B10: =SKEW('Raw Data'!B2:B190) -> -0.20863702
A13: 2. FREQUENCY DISTRIBUTION
A15: Weight Range (Kg) | B15: Frequency (Birth)
A16: 0.709-1.209 | B16: 3
A17: 1.209-1.709 | B17: 5
A18: 1.709-2.209 | B18: 21
A19: 2.209-2.709 | B19: 40
A20: 2.709-3.209 | B20: 49
A21: 3.209-3.709 | B21: 41
A22: 3.709-4.209 | B22: 27
A23: 4.209-4.709 | B23: 2
A24: 4.709-5.209 | B24: 1
A29: Interpretation:
A30: The distribution is bell-shaped with the peak at 2.709-3.209 Kg (49 births). This confirms the data follows a roughly normal pattern, supporting the use of normal distribution-based probability calculations.
A35: 3. PROBABILITY ANALYSIS
A38: Probabilitty of ≤ 2.5 Kg : | C38: Method
A39: =_xlfn.NORM.DIST(2.5,B5,B7,TRUE) -> 0.27103693 | C39: NORM.DIST(2.5, mean, std, TRUE)
A41: Value at Top 1% : | C41: Method
A42: Weight: | B42: =_xlfn.NORM.INV(1-1%,B5,B7) -> 4.6409934 | C42: NORM.INV(0.99, mean, std)
A43: Birth : | B43: {=COUNT(_xlfn._xlws.FILTER('Raw Data'!B2:B190,'Raw Data'!B2:B190>=Analysis!B42))} -> 1 | C43: COUNT(FILTER())
A45: Value at Bottom 1% : | C45: Method
A46: Weight : | B46: =_xlfn.NORM.INV(1%,B5,B7) -> 1.2481812 | C46: NORM.INV(0.01, mean, std)
A47: Birth : | B47: {=COUNT(_xlfn._xlws.FILTER('Raw Data'!B2:B190,'Raw Data'!B2:B190<=Analysis!B46))} -> 3 | C47: COUNT(FILTER())
A50: Interpretation:
A51: There is a 27.10% probability that a baby will weigh 2.5 Kg or less — this confirms the chief gynecologist's concern that over 30% of babies are low birth weight. The actual sample shows 31.2% below 2.5 Kg, which is slightly higher than the theoretical 27.10%, but within expected range given sample size. Extremely heavy (>4.641 Kg) and extremely light (<1.248 Kg) babies are rare — only 1 and 3 births respectively.
A58: 4. EMPIRICAL RULE VALIDATION
A61: EMPIRICAL RULE
A62: Std Dev from the Mean: | B62: 1 | C62: 2 | D62: 3
A63: Lower: | B63: =$B$5-B62*$B$7 -> 2.215373 | C63: =$B$5-C62*$B$7 -> 1.4861587 | D63: =$B$5-D62*$B$7 -> 0.75694442
A64: Upper: | B64: =$B$5+B62*$B$7 -> 3.6738016 | C64: =$B$5+C62*$B$7 -> 4.4030159 | D64: =$B$5+D62*$B$7 -> 5.1322302
A65: Empirical Rule: | B65: 0.68 | C65: 0.95 | D65: 0.997
A66: Sample: | B66: =COUNTIFS('Raw Data'!$B$2:$B$190, ">="&Analysis!B63,'Raw Data'!$B$2:$B$190, "<="&Analysis!B64)/COUNT('Raw Data'!$B$2:$B$190) -> 0.67724868 | C66: =COUNTIFS('Raw Data'!$B$2:$B$190, ">="&Analysis!C63,'Raw Data'!$B$2:$B$190, "<="&Analysis!C64)/COUNT('Raw Data'!$B$2:$B$190) -> 0.96296296 | D66: =COUNTIFS('Raw Data'!$B$2:$B$190, ">="&Analysis!D63,'Raw Data'!$B$2:$B$190, "<="&Analysis!D64)/COUNT('Raw Data'!$B$2:$B$190) -> 0.99470899
...

Sheet Sumarry
B2: KEY FINDINGS & CONCLUSIONS
B4: Answers to Key Objectives
B6: 1. Is the data normally distributed?
B7: YES — Mean (2.945) and median (2.977) are nearly identical, skewness is minimal (-0.209), histogram shows bell-shaped curve, and Empirical Rule validation confirms normal pattern.
B10: 2. Probability of weight <= 2.5 Kg?
B11: 27.10% — More than 1 in 4 babies are expected to be low birth weight. The actual sample rate (31.2%) is slightly higher, warranting clinical attention.
B14: 3. Top 1% and Bottom 1% values?
B15: Top 1% threshold: 4.641 Kg (1 birth above). Bottom 1% threshold: 1.248 Kg (3 births below). These represent the extreme outliers.
B18: 4. Empirical Rule validation?
B19: Sample closely matches theoretical: 67.7% vs 68% (1 SD), 96.3% vs 95% (2 SD), 99.5% vs 99.7% (3 SD). Confirms normal distribution assumption.
B23: Recommendations
B24: 1.) The 27-31% low birth weight rate is clinically significant — investigate contributing factors (maternal health, nutrition, prenatal care).
... B27: 4.) Consider collecting additional variables (gestational age, maternal age, prenatal visits) for deeper analysis.
